<?xml version="1.0" encoding="utf-8"?>
<!-- This URDF was automatically created by SolidWorks to URDF Exporter! Originally created by Stephen Brawner (brawner@gmail.com) 
     Commit Version: 1.5.1-0-g916b5db  Build Version: 1.5.7152.31018
     For more information, please see http://wiki.ros.org/sw_urdf_exporter -->
<robot
  name="rrr_urdf">
  <link
    name="base_link">
    <inertial>
      <origin
        xyz="-0.0109 0.00038703 0.016473"
        rpy="0 0 0" />
      <mass
        value="0.03728" />
      <inertia
        ixx="1.3358E-05"
        ixy="6.0492E-20"
        ixz="1.1845E-19"
        iyy="2.281E-05"
        iyz="2.8666E-09"
        izz="3.066E-05" />
    </inertial>
    <visual>
      <origin
        xyz="0 0 0"
        rpy="0 0 0" />
      <geometry>
        <mesh
          filename="package://rrr_urdf/meshes/base_link.STL" />
      </geometry>
      <material
        name="">
        <color
          rgba="0.75294 0.75294 0.75294 1" />
      </material>
    </visual>
    <collision>
      <origin
        xyz="0 0 0"
        rpy="0 0 0" />
      <geometry>
        <mesh
          filename="package://rrr_urdf/meshes/base_link.STL" />
      </geometry>
    </collision>
  </link>
  <link
    name="servo1">
    <inertial>
      <origin
        xyz="-0.010364 7.6328E-17 -0.022538"
        rpy="0 0 0" />
      <mass
        value="0.032502" />
      <inertia
        ixx="5.0164E-06"
        ixy="-7.6479E-23"
        ixz="-2.4157E-08"
        iyy="8.9391E-06"
        iyz="8.7187E-21"
        izz="6.1041E-06" />
    </inertial>
    <visual>
      <origin
        xyz="0 0 0"
        rpy="0 0 0" />
      <geometry>
        <mesh
          filename="package://rrr_urdf/meshes/servo1.STL" />
      </geometry>
      <material
        name="">
        <color
          rgba="0.43137 0.45098 0.43137 1" />
      </material>
    </visual>
    <collision>
      <origin
        xyz="0 0 0"
        rpy="0 0 0" />
      <geometry>
        <mesh
          filename="package://rrr_urdf/meshes/servo1.STL" />
      </geometry>
    </collision>
  </link>
  <joint
    name="servo1_joint"
    type="fixed">
    <origin
      xyz="0 0.00076901 0.0689"
      rpy="0 0 0" />
    <parent
      link="base_link" />
    <child
      link="servo1" />
    <axis
      xyz="0 0 0" />
  </joint>
  <link
    name="link1">
    <inertial>
      <origin
        xyz="0.030628 -2.6829E-06 -0.0025"
        rpy="0 0 0" />
      <mass
        value="0.0064291" />
      <inertia
        ixx="3.086E-07"
        ixy="-1.093E-10"
        ixz="1.1233E-22"
        iyy="5.8786E-06"
        iyz="-9.9506E-22"
        izz="6.1775E-06" />
    </inertial>
    <visual>
      <origin
        xyz="0 0 0"
        rpy="0 0 0" />
      <geometry>
        <mesh
          filename="package://rrr_urdf/meshes/link1.STL" />
      </geometry>
      <material
        name="">
        <color
          rgba="1 0.16863 0.16863 1" />
      </material>
    </visual>
    <collision>
      <origin
        xyz="0 0 0"
        rpy="0 0 0" />
      <geometry>
        <mesh
          filename="package://rrr_urdf/meshes/link1.STL" />
      </geometry>
    </collision>
  </link>
  <joint
    name="link1_joint"
    type="revolute">
    <origin
      xyz="0 0 0"
      rpy="0 0 0" />
    <parent
      link="servo1" />
    <child
      link="link1" />
    <axis
      xyz="0 0 1" />
    <limit
      lower="-2.5708"
      upper="2.5708"
      effort="1"
      velocity="0.5" />
  </joint>
  <transmission name="simple_trans_2">
     <type>transmission_interface/SimpleTransmission</type>
     <joint name="link1_joint">
       <hardwareInterface>hardware_interface/EffortJointInterface</hardwareInterface>
       </joint>
     <actuator name="link1_joint_motor">
       <mechanicalReduction>1</mechanicalReduction>
       <hardwareInterface>EffortJointInterface</hardwareInterface>
       </actuator>
   </transmission>
  <link
    name="servo2">
    <inertial>
      <origin
        xyz="-0.0047673 -1.637E-06 -0.017232"
        rpy="0 0 0" />
      <mass
        value="0.0071183" />
      <inertia
        ixx="1.3612E-07"
        ixy="-6.5334E-11"
        ixz="-9.7433E-09"
        iyy="3.7352E-07"
        iyz="-6.4178E-12"
        izz="4.0596E-07" />
    </inertial>
    <visual>
      <origin
        xyz="0 0 0"
        rpy="0 0 0" />
      <geometry>
        <mesh
          filename="package://rrr_urdf/meshes/servo2.STL" />
      </geometry>
      <material
        name="">
        <color
          rgba="0.79216 0.81961 0.93333 1" />
      </material>
    </visual>
    <collision>
      <origin
        xyz="0 0 0"
        rpy="0 0 0" />
      <geometry>
        <mesh
          filename="package://rrr_urdf/meshes/servo2.STL" />
      </geometry>
    </collision>
  </link>
  <joint
    name="servo2_joint"
    type="fixed">
    <origin
      xyz="0.074352 1.3313E-05 0.01315"
      rpy="0 0 0" />
    <parent
      link="link1" />
    <child
      link="servo2" />
    <axis
      xyz="0 0 0" />
  </joint>
  <link
    name="link2">
    <inertial>
      <origin
        xyz="0.029293 -2.5659E-06 -0.0015222"
        rpy="0 0 0" />
      <mass
        value="0.0067222" />
      <inertia
        ixx="3.0966E-07"
        ixy="-5.8306E-10"
        ixz="-4.9501E-23"
        iyy="5.8964E-06"
        iyz="-1.0397E-21"
        izz="6.196E-06" />
    </inertial>
    <visual>
      <origin
        xyz="0 0 0"
        rpy="0 0 0" />
      <geometry>
        <mesh
          filename="package://rrr_urdf/meshes/link2.STL" />
      </geometry>
      <material
        name="">
        <color
          rgba="1 0.16863 0.16863 1" />
      </material>
    </visual>
    <collision>
      <origin
        xyz="0 0 0"
        rpy="0 0 0" />
      <geometry>
        <mesh
          filename="package://rrr_urdf/meshes/link2.STL" />
      </geometry>
    </collision>
  </link>
  <joint
    name="link2_joint"
    type="revolute">
    <origin
      xyz="0 0 0"
      rpy="0 0 0" />
    <parent
      link="servo2" />
    <child
      link="link2" />
    <axis
      xyz="0 0 1" />
    <limit
      lower="-2.5708"
      upper="2.5708"
      effort="1"
      velocity="0.5" />
  </joint>
  <transmission name="simple_trans_1">
     <type>transmission_interface/SimpleTransmission</type>
     <joint name="link2_joint">
       <hardwareInterface>hardware_interface/EffortJointInterface</hardwareInterface>
       </joint>
     <actuator name="link2_joint_motor">
       <hardwareInterface>EffortJointInterface</hardwareInterface>
       <mechanicalReduction>1</mechanicalReduction>
       </actuator>
   </transmission>
  <link
    name="servo3">
    <inertial>
      <origin
        xyz="-0.0047673 -1.637E-06 -0.017232"
        rpy="0 0 0" />
      <mass
        value="0.0071183" />
      <inertia
        ixx="1.3612E-07"
        ixy="-6.5334E-11"
        ixz="-9.7433E-09"
        iyy="3.7352E-07"
        iyz="-6.4178E-12"
        izz="4.0596E-07" />
    </inertial>
    <visual>
      <origin
        xyz="0 0 0"
        rpy="0 0 0" />
      <geometry>
        <mesh
          filename="package://rrr_urdf/meshes/servo3.STL" />
      </geometry>
      <material
        name="">
        <color
          rgba="0.79216 0.81961 0.93333 1" />
      </material>
    </visual>
    <collision>
      <origin
        xyz="0 0 0"
        rpy="0 0 0" />
      <geometry>
        <mesh
          filename="package://rrr_urdf/meshes/servo3.STL" />
      </geometry>
    </collision>
  </link>
  <joint
    name="servo3_joint"
    type="fixed">
    <origin
      xyz="0.075948 -2.2418E-05 0.01405"
      rpy="0 0 0" />
    <parent
      link="link2" />
    <child
      link="servo3" />
    <axis
      xyz="0 0 0" />
  </joint>
  <link
    name="link3">
    <inertial>
      <origin
        xyz="0.031744 -6.245E-17 -0.0015274"
        rpy="0 0 0" />
      <mass
        value="0.0072029" />
      <inertia
        ixx="3.1538E-07"
        ixy="-7.7492E-10"
        ixz="1.1695E-23"
        iyy="6.6268E-06"
        iyz="4.347E-23"
        izz="6.9314E-06" />
    </inertial>
    <visual>
      <origin
        xyz="0 0 0"
        rpy="0 0 0" />
      <geometry>
        <mesh
          filename="package://rrr_urdf/meshes/link3.STL" />
      </geometry>
      <material
        name="">
        <color
          rgba="1 0.16863 0.16863 1" />
      </material>
    </visual>
    <collision>
      <origin
        xyz="0 0 0"
        rpy="0 0 0" />
      <geometry>
        <mesh
          filename="package://rrr_urdf/meshes/link3.STL" />
      </geometry>
    </collision>
  </link>
  <joint
    name="link3_joint"
    type="revolute">
    <origin
      xyz="0 0 0"
      rpy="0 0 0" />
    <parent
      link="servo3" />
    <child
      link="link3" />
    <axis
      xyz="0 0 1" />
    <limit
      lower="-2.5708"
      upper="2.5708"
      effort="1"
      velocity="0.5" />
  </joint>
  <transmission name="simple_trans">
     <type>transmission_interface/SimpleTransmission</type>
     <joint name="link3_joint">
       <hardwareInterface>hardware_interface/EffortJointInterface</hardwareInterface>
       </joint>
     <actuator name="link3_joint_motor">
       <mechanicalReduction>1</mechanicalReduction>
       <hardwareInterface>EffortJointInterface</hardwareInterface>
       </actuator>
   </transmission>
  <link
    name="pen">
    <inertial>
      <origin
        xyz="9.4369E-16 1.3184E-16 -0.028712"
        rpy="0 0 0" />
      <mass
        value="0.019305" />
      <inertia
        ixx="2.5556E-05"
        ixy="-8.9414E-25"
        ixz="4.5462E-20"
        iyy="2.5556E-05"
        iyz="-7.4657E-22"
        izz="4.7156E-07" />
    </inertial>
    <visual>
      <origin
        xyz="0 0 0"
        rpy="0 0 0" />
      <geometry>
        <mesh
          filename="package://rrr_urdf/meshes/pen.STL" />
      </geometry>
      <material
        name="">
        <color
          rgba="1 1 0 1" />
      </material>
    </visual>
    <collision>
      <origin
        xyz="0 0 0"
        rpy="0 0 0" />
      <geometry>
        <mesh
          filename="package://rrr_urdf/meshes/pen.STL" />
      </geometry>
    </collision>
  </link>
  <joint
    name="pen_joint"
    type="fixed">
    <origin
      xyz="0.07 0 -0.0001"
      rpy="0 0 0" />
    <parent
      link="link3" />
    <child
      link="pen" />
    <axis
      xyz="0 0 0" />
  </joint>
  <gazebo>
  <plugin name="gazebo_ros_control" filename="libgazebo_ros_control.so">
  </plugin>
  </gazebo>
</robot>
